Workbook

Sheet README
A1: S1 Data | Monthly analysis observations and Figure 2 supporting data
A3: Field | B3: Description
A4: Working paper | B4: Renminbi-denominated oil-price movements and inflation dynamics across China’s price system
A5: Main observations | B5: Monthly_338: 1998-01 through 2026-02; 338 monthly rows
A6: Customs observations | B6: Customs_134: 2015-01 through 2026-02; HS 27090000 only, 134 rows
A7: Figure 2 source | B7: Fig2_observations: long format reconstructed from author-supplied raw inputs, NOT the old private 7,774-row figure export
A8: Raw file fingerprint | B8: 10/10 primary input SHA256 match released repository config/raw_inputs.json
A9: Provenance | B9: Author-supplied 01_raw.zip, using original EIA/FRED/NBS/Customs series; third-party terms remain applicable
A10: Primary outcome | B10: Monthly change in year-on-year inflation, in percentage points, not month-on-month price inflation
A11: Shock variable | B11: 100 x calendar-month log change of Brent USD/barrel times CNY/USD
A12: Lag/lead policy | B12: Primary LP two oil-change and two outcome lags; h=0–12 with calendar-aware observations
A13: Missing data | B13: Blank means unavailable or undefined at transformation boundary; zeros are actual zeros
A14: Publication status | B14: Final supporting dataset for journal submission. Observation-level and sample consistency checks completed; full independent statistical re-estimation was not performed.
A15: Archive identity | B15: Supplementary file distinct from GitHub v2.0.0 / Zenodo DOI 10.5281/zenodo.23388839
A16: Do not label independent 39-model / MBB / full figure recreation as verified from this workbook; consult the repository VALIDATION.md.
A17: Files in this workbook are reconstructed observations. Recomputing regression tables requires the released analysis scripts and historical environment.
A18: Short-sample transformation boundary | B18: For the formal customs-sample stationary data, restrict the calendar to January 2015–February 2026 before computing differences. January 2015 is the transformation boundary. Full-calendar macroeconomic changes remain unchanged in Monthly_338.
A19: Estimation-sample indicators | B19: The link1_origin flag identifies the 130 Customs Link 1 months beginning in May 2015. Primary LP eligibility indicators refer only to the long-sample macroeconomic models and must not be substituted for customs-sample eligibility.

Sheet Monthly_338
A1: month | B1: brent_usd_per_bbl | C1: cny_per_usd | D1: oil_rmb_cny_per_bbl | E1: dlog_brent | F1: dlog_fx | G1: dlog_oil_rmb | H1: fuel_index_yoy | I1: ppi_index_yoy | J1: cpi_index_yoy | K1: d_fuel_power_inflation | L1: d_ppi_inflation | M1: d_cpi_inflation | N1: purchase_index_yoy | O1: indust_va_yoy | P1: indust_va_cum_yoy | Q1: lp_origin_h0 | R1: lp_origin_h3 | S1: lp_origin_h6 | T1: lp_origin_h12
A2: 1998-01 | B2: 15.19 | C2: 8.3094 | D2: =B2*C2 -> 126.21979 | E2: ="" | F2: ="" | G2: ="" | H2: 105.9 | I2: 98.7 | J2: 100.3 | K2: ="" | L2: ="" | M2: ="" | N2: 99.6 | Q2: =IF(ROW()>=5,1,0) -> 0 | R2: =IF(AND(ROW()>=5,ROW()+3<=339),1,0) -> 0 | S2: =IF(AND(ROW()>=5,ROW()+6<=339),1,0) -> 0 | T2: =IF(AND(ROW()>=5,ROW()+12<=339),1,0) -> 0
A3: 1998-02 | B3: 14.07 | C3: 8.3072 | D3: =B3*C3 -> 116.8823 | E3: =100*LN(B3/B2) -> -7.6592445 | F3: =100*LN(C3/C2) -> -0.026479545 | G3: =100*LN(D3/D2) -> -7.6857241 | H3: 101.5 | I3: 97.4 | J3: 99.9 | K3: =H3-H2 -> -4.4 | L3: =I3-I2 -> -1.3 | M3: =J3-J2 -> -0.4 | N3: 98.3 | Q3: =IF(ROW()>=5,1,0) -> 0 | R3: =IF(AND(ROW()>=5,ROW()+3<=339),1,0) -> 0 | S3: =IF(AND(ROW()>=5,ROW()+6<=339),1,0) -> 0 | T3: =IF(AND(ROW()>=5,ROW()+12<=339),1,0) -> 0
A4: 1998-03 | B4: 13.1 | C4: 8.3076 | D4: =B4*C4 -> 108.82956 | E4: =100*LN(B4/B3) -> -7.1432641 | F4: =100*LN(C4/C3) -> 0.0048149842 | G4: =100*LN(D4/D3) -> -7.1384491 | H4: 100.7 | I4: 96.8 | J4: 100.7 | K4: =H4-H3 -> -0.8 | L4: =I4-I3 -> -0.6 | M4: =J4-J3 -> 0.8 | N4: 97.7 | Q4: =IF(ROW()>=5,1,0) -> 0 | R4: =IF(AND(ROW()>=5,ROW()+3<=339),1,0) -> 0 | S4: =IF(AND(ROW()>=5,ROW()+6<=339),1,0) -> 0 | T4: =IF(AND(ROW()>=5,ROW()+12<=339),1,0) -> 0
A5: 1998-04 | B5: 13.53 | C5: 8.3058 | D5: =B5*C5 -> 112.37747 | E5: =100*LN(B5/B4) -> 3.2297212 | F5: =100*LN(C5/C4) -> -0.021669255 | G5: =100*LN(D5/D4) -> 3.2080519 | H5: 100.3 | I5: 96.3 | J5: 99.7 | K5: =H5-H4 -> -0.4 | L5: =I5-I4 -> -0.5 | M5: =J5-J4 -> -1 | N5: 97.3 | Q5: =IF(ROW()>=5,1,0) -> 1 | R5: =IF(AND(ROW()>=5,ROW()+3<=339),1,0) -> 1 | S5: =IF(AND(ROW()>=5,ROW()+6<=339),1,0) -> 1 | T5: =IF(AND(ROW()>=5,ROW()+12<=339),1,0) -> 1
A6: 1998-05 | B6: 14.36 | C6: 8.3084 | D6: =B6*C6 -> 119.30862 | E6: =100*LN(B6/B5) -> 5.9537121 | F6: =100*LN(C6/C5) -> 0.031298528 | G6: =100*LN(D6/D5) -> 5.9850107 | H6: 98.4 | I6: 95.5 | J6: 99 | K6: =H6-H5 -> -1.9 | L6: =I6-I5 -> -0.8 | M6: =J6-J5 -> -0.7 | N6: 94.7 | Q6: =IF(ROW()>=5,1,0) -> 1 | R6: =IF(AND(ROW()>=5,ROW()+3<=339),1,0) -> 1 | S6: =IF(AND(ROW()>=5,ROW()+6<=339),1,0) -> 1 | T6: =IF(AND(ROW()>=5,ROW()+12<=339),1,0) -> 1
A7: 1998-06 | B7: 12.21 | C7: 8.31 | D7: =B7*C7 -> 101.4651 | E7: =100*LN(B7/B6) -> -16.219128 | F7: =100*LN(C7/C6) -> 0.019255765 | G7: =100*LN(D7/D6) -> -16.199872 | H7: 98.4 | I7: 95.1 | J7: 98.7 | K7: =H7-H6 -> 0 | L7: =I7-I6 -> -0.4 | M7: =J7-J6 -> -0.3 | N7: 94.8 | Q7: =IF(ROW()>=5,1,0) -> 1 | R7: =IF(AND(ROW()>=5,ROW()+3<=339),1,0) -> 1 | S7: =IF(AND(ROW()>=5,ROW()+6<=339),1,0) -> 1 | T7: =IF(AND(ROW()>=5,ROW()+12<=339),1,0) -> 1
A8: 1998-07 | B8: 12.08 | C8: 8.31 | D8: =B8*C8 -> 100.3848 | E8: =100*LN(B8/B7) -> -1.0704096 | F8: =100*LN(C8/C7) -> 0 | G8: =100*LN(D8/D7) -> -1.0704096 | H8: 95.8 | I8: 95 | J8: 98.6 | K8: =H8-H7 -> -2.6 | L8: =I8-I7 -> -0.1 | M8: =J8-J7 -> -0.1 | N8: 94 | O8: 7.6 | P8: 7.8 | Q8: =IF(ROW()>=5,1,0) -> 1 | R8: =IF(AND(ROW()>=5,ROW()+3<=339),1,0) -> 1 | S8: =IF(AND(ROW()>=5,ROW()+6<=339),1,0) -> 1 | T8: =IF(AND(ROW()>=5,ROW()+12<=339),1,0) -> 1
A9: 1998-08 | B9: 11.91 | C9: 8.31 | D9: =B9*C9 -> 98.9721 | E9: =100*LN(B9/B8) -> -1.4172809 | F9: =100*LN(C9/C8) -> 0 | G9: =100*LN(D9/D8) -> -1.4172809 | H9: 95.7 | I9: 94.5 | J9: 98.6 | K9: =H9-H8 -> -0.1 | L9: =I9-I8 -> -0.5 | M9: =J9-J8 -> 0 | N9: 92.9 | O9: 7.9 | P9: 7.8 | Q9: =IF(ROW()>=5,1,0) -> 1 | R9: =IF(AND(ROW()>=5,ROW()+3<=339),1,0) -> 1 | S9: =IF(AND(ROW()>=5,ROW()+6<=339),1,0) -> 1 | T9: =IF(AND(ROW()>=5,ROW()+12<=339),1,0) -> 1
A10: 1998-09 | B10: 13.34 | C10: 8.3055 | D10: =B10*C10 -> 110.79537 | E10: =100*LN(B10/B9) -> 11.338866 | F10: =100*LN(C10/C9) -> -0.054166292 | G10: =100*LN(D10/D9) -> 11.284699 | H10: 95.7 | I10: 95.8 | J10: 98.5 | K10: =H10-H9 -> 0 | L10: =I10-I9 -> 1.3 | M10: =J10-J9 -> -0.1 | N10: 94.1 | O10: 10.2 | P10: 8 | Q10: =IF(ROW()>=5,1,0) -> 1 | R10: =IF(AND(ROW()>=5,ROW()+3<=339),1,0) -> 1 | S10: =IF(AND(ROW()>=5,ROW()+6<=339),1,0) -> 1 | T10: =IF(AND(ROW()>=5,ROW()+12<=339),1,0) -> 1
A11: 1998-10 | B11: 12.7 | C11: 8.2778 | D11: =B11*C11 -> 105.12806 | E11: =100*LN(B11/B10) -> -4.9165047 | F11: =100*LN(C11/C10) -> -0.33407133 | G11: =100*LN(D11/D10) -> -5.250576 | H11: 97 | I11: 94.3 | J11: 98.9 | K11: =H11-H10 -> 1.3 | L11: =I11-I10 -> -1.5 | M11: =J11-J10 -> 0.4 | N11: 93.9 | O11: 10.6 | P11: 8.2 | Q11: =IF(ROW()>=5,1,0) -> 1 | R11: =IF(AND(ROW()>=5,ROW()+3<=339),1,0) -> 1 | S11: =IF(AND(ROW()>=5,ROW()+6<=339),1,0) -> 1 | T11: =IF(AND(ROW()>=5,ROW()+12<=339),1,0) -> 1
A12: 1998-11 | B12: 11.04 | C12: 8.2778 | D12: =B12*C12 -> 91.386912 | E12: =100*LN(B12/B11) -> -14.007695 | F12: =100*LN(C12/C11) -> 0 | G12: =100*LN(D12/D11) -> -14.007695 | H12: 96.8 | I12: 94.6 | J12: 98.8 | K12: =H12-H11 -> -0.2 | L12: =I12-I11 -> 0.3 | M12: =J12-J11 -> -0.1 | N12: 93.9 | O12: 11 | P12: 8.5 | Q12: =IF(ROW()>=5,1,0) -> 1 | R12: =IF(AND(ROW()>=5,ROW()+3<=339),1,0) -> 1 | S12: =IF(AND(ROW()>=5,ROW()+6<=339),1,0) -> 1 | T12: =IF(AND(ROW()>=5,ROW()+12<=339),1,0) -> 1
A13: 1998-12 | B13: 9.82 | C13: 8.278 | D13: =B13*C13 -> 81.28996 | E13: =100*LN(B13/B12) -> -11.710392 | F13: =100*LN(C13/C12) -> 0.0024160717 | G13: =100*LN(D13/D12) -> -11.707976 | H13: 96.4 | I13: 96.2 | J13: 99 | K13: =H13-H12 -> -0.4 | L13: =I13-I12 -> 1.6 | M13: =J13-J12 -> 0.2 | N13: 93.9 | O13: 11.5 | P13: 8.8 | Q13: =IF(ROW()>=5,1,0) -> 1 | R13: =IF(AND(ROW()>=5,ROW()+3<=339),1,0) -> 1 | S13: =IF(AND(ROW()>=5,ROW()+6<=339),1,0) -> 1 | T13: =IF(AND(ROW()>=5,ROW()+12<=339),1,0) -> 1
A14: 1999-01 | B14: 11.11 | C14: 8.2789 | D14: =B14*C14 -> 91.978579 | E14: =100*LN(B14/B13) -> 12.342448 | F14: =100*LN(C14/C13) -> 0.0108716 | G14: =100*LN(D14/D13) -> 12.35332 | H14: 95.4 | I14: 95.1 | J14: 98.8 | K14: =H14-H13 -> -1 | L14: =I14-I13 -> -1.1 | M14: =J14-J13 -> -0.2 | N14: 92.7 | Q14: =IF(ROW()>=5,1,0) -> 1 | R14: =IF(AND(ROW()>=5,ROW()+3<=339),1,0) -> 1 | S14: =IF(AND(ROW()>=5,ROW()+6<=339),1,0) -> 1 | T14: =IF(AND(ROW()>=5,ROW()+12<=339),1,0) -> 1
A15: 1999-02 | B15: 10.27 | C15: 8.2781 | D15: =B15*C15 -> 85.016087 | E15: =100*LN(B15/B14) -> -7.861858 | F15: =100*LN(C15/C14) -> -0.0096635864 | G15: =100*LN(D15/D14) -> -7.8715216 | H15: 94.3 | I15: 95.1 | J15: 98.7 | K15: =H15-H14 -> -1.1 | L15: =I15-I14 -> 0 | M15: =J15-J14 -> -0.1 | N15: 93.2 | O15: 2.1 | P15: 10.6 | Q15: =IF(ROW()>=5,1,0) -> 1 | R15: =IF(AND(ROW()>=5,ROW()+3<=339),1,0) -> 1 | S15: =IF(AND(ROW()>=5,ROW()+6<=339),1,0) -> 1 | T15: =IF(AND(ROW()>=5,ROW()+12<=339),1,0) -> 1
A16: 1999-03 | B16: 12.51 | C16: 8.2792 | D16: =B16*C16 -> 103.57279 | E16: =100*LN(B16/B15) -> 19.73013 | F16: =100*LN(C16/C15) -> 0.013287191 | G16: =100*LN(D16/D15) -> 19.743417 | H16: 95.3 | I16: 95.4 | J16: 98.2 | K16: =H16-H15 -> 1 | L16: =I16-I15 -> 0.3 | M16: =J16-J15 -> -0.5 | N16: 93.5 | O16: 9 | P16: 10.1 | Q16: =IF(ROW()>=5,1,0) -> 1 | R16: =IF(AND(ROW()>=5,ROW()+3<=339),1,0) -> 1 | S16: =IF(AND(ROW()>=5,ROW()+6<=339),1,0) -> 1 | T16: =IF(AND(ROW()>=5,ROW()+12<=339),1,0) -> 1
A17: 1999-04 | B17: 15.29 | C17: 8.2792 | D17: =B17*C17 -> 126.58897 | E17: =100*LN(B17/B16) -> 20.06707 | F17: =100*LN(C17/C16) -> 0 | G17: =100*LN(D17/D16) -> 20.06707 | H17: 96.1 | I17: 96.1 | J17: 97.8 | K17: =H17-H16 -> 0.8 | L17: =I17-I16 -> 0.7 | M17: =J17-J16 -> -0.4 | N17: 93.7 | O17: 9.1 | P17: 9.7 | Q17: =IF(ROW()>=5,1,0) -> 1 | R17: =IF(AND(ROW()>=5,ROW()+3<=339),1,0) -> 1 | S17: =IF(AND(ROW()>=5,ROW()+6<=339),1,0) -> 1 | T17: =IF(AND(ROW()>=5,ROW()+12<=339),1,0) -> 1
A18: 1999-05 | B18: 15.23 | C18: 8.2785 | D18: =B18*C18 -> 126.08155 | E18: =100*LN(B18/B17) -> -0.3931853 | F18: =100*LN(C18/C17) -> -0.0084552806 | G18: =100*LN(D18/D17) -> -0.40164058 | H18: 98.3 | I18: 96.6 | J18: 97.8 | K18: =H18-H17 -> 2.2 | L18: =I18-I17 -> 0.5 | M18: =J18-J17 -> 0 | N18: 95.1 | O18: 8.9 | P18: 9.5 | Q18: =IF(ROW()>=5,1,0) -> 1 | R18: =IF(AND(ROW()>=5,ROW()+3<=339),1,0) -> 1 | S18: =IF(AND(ROW()>=5,ROW()+6<=339),1,0) -> 1 | T18: =IF(AND(ROW()>=5,ROW()+12<=339),1,0) -> 1
A19: 1999-06 | B19: 15.86 | C19: 8.278 | D19: =B19*C19 -> 131.28908 | E19: =100*LN(B19/B18) -> 4.0533049 | F19: =100*LN(C19/C18) -> -0.0060399239 | G19: =100*LN(D19/D18) -> 4.047265 | H19: 99.4 | I19: 96.4 | J19: 97.9 | K19: =H19-H18 -> 1.1 | L19: =I19-I18 -> -0.2 | M19: =J19-J18 -> 0.1 | N19: 95.1 | O19: 9.1 | P19: 9.4 | Q19: =IF(ROW()>=5,1,0) -> 1 | R19: =IF(AND(ROW()>=5,ROW()+3<=339),1,0) -> 1 | S19: =IF(AND(ROW()>=5,ROW()+6<=339),1,0) -> 1 | T19: =IF(AND(ROW()>=5,ROW()+12<=339),1,0) -> 1
A20: 1999-07 | B20: 19.08 | C20: 8.2776 | D20: =B20*C20 -> 157.93661 | E20: =100*LN(B20/B19) -> 18.484045 | F20: =100*LN(C20/C19) -> -0.0048322018 | G20: =100*LN(D20/D19) -> 18.479213 | H20: 100.3 | I20: 97.5 | J20: 98.6 | K20: =H20-H19 -> 0.9 | L20: =I20-I19 -> 1.1 | M20: =J20-J19 -> 0.7 | N20: 96.6 | O20: 9.3 | P20: 9.4 | Q20: =IF(ROW()>=5,1,0) -> 1 | R20: =IF(AND(ROW()>=5,ROW()+3<=339),1,0) -> 1 | S20: =IF(AND(ROW()>=5,ROW()+6<=339),1,0) -> 1 | T20: =IF(AND(ROW()>=5,ROW()+12<=339),1,0) -> 1
A21: 1999-08 | B21: 20.22 | C21: 8.2772 | D21: =B21*C21 -> 167.36498 | E21: =100*LN(B21/B20) -> 5.8031548 | F21: =100*LN(C21/C20) -> -0.0048324353 | G21: =100*LN(D21/D20) -> 5.7983223 | H21: 103.1 | I21: 97.7 | J21: 98.7 | K21: =H21-H20 -> 2.8 | L21: =I21-I20 -> 0.2 | M21: =J21-J20 -> 0.1 | N21: 96.7 | O21: 9.5 | P21: 9.4 | Q21: =IF(ROW()>=5,1,0) -> 1 | R21: =IF(AND(ROW()>=5,ROW()+3<=339),1,0) -> 1 | S21: =IF(AND(ROW()>=5,ROW()+6<=339),1,0) -> 1 | T21: =IF(AND(ROW()>=5,ROW()+12<=339),1,0) -> 1
A22: 1999-09 | B22: 22.54 | C22: 8.2774 | D22: =B22*C22 -> 186.5726 | E22: =100*LN(B22/B21) -> 10.86193 | F22: =100*LN(C22/C21) -> 0.0024162468 | G22: =100*LN(D22/D21) -> 10.864346 | H22: 103.1 | I22: 97.9 | J22: 99.2 | K22: =H22-H21 -> 0 | L22: =I22-I21 -> 0.2 | M22: =J22-J21 -> 0.5 | N22: 98.2 | O22: 8.2 | P22: 9.3 | Q22: =IF(ROW()>=5,1,0) -> 1 | R22: =IF(AND(ROW()>=5,ROW()+3<=339),1,0) -> 1 | S22: =IF(AND(ROW()>=5,ROW()+6<=339),1,0) -> 1 | T22: =IF(AND(ROW()>=5,ROW()+12<=339),1,0) -> 1
A23: 1999-10 | B23: 22 | C23: 8.2775 | D23: =B23*C23 -> 182.105 | E23: =100*LN(B23/B22) -> -2.4249055 | F23: =100*LN(C23/C22) -> 0.0012081015 | G23: =100*LN(D23/D22) -> -2.4236974 | H23: 107.1 | I23: 99.3 | J23: 99.4 | K23: =H23-H22 -> 4 | L23: =I23-I22 -> 1.4 | M23: =J23-J22 -> 0.2 | N23: 98.9 | O23: 7 | P23: 9.1 | Q23: =IF(ROW()>=5,1,0) -> 1 | R23: =IF(AND(ROW()>=5,ROW()+3<=339),1,0) -> 1 | S23: =IF(AND(ROW()>=5,ROW()+6<=339),1,0) -> 1 | T23: =IF(AND(ROW()>=5,ROW()+12<=339),1,0) -> 1
A24: 1999-11 | B24: 24.58 | C24: 8.2782 | D24: =B24*C24 -> 203.47816 | E24: =100*LN(B24/B23) -> 11.089065 | F24: =100*LN(C24/C23) -> 0.0084563021 | G24: =100*LN(D24/D23) -> 11.097521 | H24: 104.6 | I24: 98.9 | J24: 99.1 | K24: =H24-H23 -> -2.5 | L24: =I24-I23 -> -0.4 | M24: =J24-J23 -> -0.3 | N24: 98.3 | O24: 7.6 | P24: 9 | Q24: =IF(ROW()>=5,1,0) -> 1 | R24: =IF(AND(ROW()>=5,ROW()+3<=339),1,0) -> 1 | S24: =IF(AND(ROW()>=5,ROW()+6<=339),1,0) -> 1 | T24: =IF(AND(ROW()>=5,ROW()+12<=339),1,0) -> 1
A25: 1999-12 | B25: 25.47 | C25: 8.2794 | D25: =B25*C25 -> 210.87632 | E25: =100*LN(B25/B24) -> 3.5568185 | F25: =100*LN(C25/C24) -> 0.014494854 | G25: =100*LN(D25/D24) -> 3.5713133 | H25: 110.3 | I25: 99.2 | J25: 99 | K25: =H25-H24 -> 5.7 | L25: =I25-I24 -> 0.3 | M25: =J25-J24 -> -0.1 | N25: 100.8 | O25: 7.4 | P25: 8.9 | Q25: =IF(ROW()>=5,1,0) -> 1 | R25: =IF(AND(ROW()>=5,ROW()+3<=339),1,0) -> 1 | S25: =IF(AND(ROW()>=5,ROW()+6<=339),1,0) -> 1 | T25: =IF(AND(ROW()>=5,ROW()+12<=339),1,0) -> 1
A26: 2000-01 | B26: 25.51 | C26: 8.2792 | D26: =B26*C26 -> 211.20239 | E26: =100*LN(B26/B25) -> 0.15692432 | F26: =100*LN(C26/C25) -> -0.0024156632 | G26: =100*LN(D26/D25) -> 0.15450865 | H26: 113.2 | I26: 100 | J26: 99.8 | K26: =H26-H25 -> 2.9 | L26: =I26-I25 -> 0.8 | M26: =J26-J25 -> 0.8 | N26: 102.1 | Q26: =IF(ROW()>=5,1,0) -> 1 | R26: =IF(AND(ROW()>=5,ROW()+3<=339),1,0) -> 1 | S26: =IF(AND(ROW()>=5,ROW()+6<=339),1,0) -> 1 | T26: =IF(AND(ROW()>=5,ROW()+12<=339),1,0) -> 1
A27: 2000-02 | B27: 27.78 | C27: 8.2781 | D27: =B27*C27 -> 229.96562 | E27: =100*LN(B27/B26) -> 8.5245805 | F27: =100*LN(C27/C26) -> -0.013287191 | G27: =100*LN(D27/D26) -> 8.5112933 | H27: 114.1 | I27: 101 | J27: 100.7 | K27: =H27-H26 -> 0.9 | L27: =I27-I26 -> 1 | M27: =J27-J26 -> 0.9 | N27: 103.6 | O27: 12 | P27: 10.4 | Q27: =IF(ROW()>=5,1,0) -> 1 | R27: =IF(AND(ROW()>=5,ROW()+3<=339),1,0) -> 1 | S27: =IF(AND(ROW()>=5,ROW()+6<=339),1,0) -> 1 | T27: =IF(AND(ROW()>=5,ROW()+12<=339),1,0) -> 1
A28: 2000-03 | B28: 27.49 | C28: 8.2786 | D28: =B28*C28 -> 227.57871 | E28: =100*LN(B28/B27) -> -1.0494035 | F28: =100*LN(C28/C27) -> 0.0060398509 | G28: =100*LN(D28/D27) -> -1.0433637 | H28: 115.7 | I28: 101.9 | J28: 99.8 | K28: =H28-H27 -> 1.6 | L28: =I28-I27 -> 0.9 | M28: =J28-J27 -> -0.9 | N28: 104.8 | O28: 11.9 | P28: 10.7 | Q28: =IF(ROW()>=5,1,0) -> 1 | R28: =IF(AND(ROW()>=5,ROW()+3<=339),1,0) -> 1 | S28: =IF(AND(ROW()>=5,ROW()+6<=339),1,0) -> 1 | T28: =IF(AND(ROW()>=5,ROW()+12<=339),1,0) -> 1
A29: 2000-04 | B29: 22.76 | C29: 8.2793 | D29: =B29*C29 -> 188.43687 | E29: =100*LN(B29/B28) -> -18.881769 | F29: =100*LN(C29/C28) -> 0.0084551785 | G29: =100*LN(D29/D28) -> -18.873314 | H29: 116.5 | I29: 102.6 | J29: 99.7 | K29: =H29-H28 -> 0.8 | L29: =I29-I28 -> 0.7 | M29: =J29-J28 -> -0.1 | N29: 105.3 | O29: 11.4 | P29: 10.9 | Q29: =IF(ROW()>=5,1,0) -> 1 | R29: =IF(AND(ROW()>=5,ROW()+3<=339),1,0) -> 1 | S29: =IF(AND(ROW()>=5,ROW()+6<=339),1,0) -> 1 | T29: =IF(AND(ROW()>=5,ROW()+12<=339),1,0) -> 1
A30: 2000-05 | B30: 27.74 | C30: 8.2781 | D30: =B30*C30 -> 229.63449 | E30: =100*LN(B30/B29) -> 19.787081 | F30: =100*LN(C30/C29) -> -0.014495029 | G30: =100*LN(D30/D29) -> 19.772586 | H30: 111.9 | I30: 102.5 | J30: 100.1 | K30: =H30-H29 -> -4.6 | L30: =I30-I29 -> -0.1 | M30: =J30-J29 -> 0.4 | N30: 105.5 | O30: 11.5 | P30: 11 | Q30: =IF(ROW()>=5,1,0) -> 1 | R30: =IF(AND(ROW()>=5,ROW()+3<=339),1,0) -> 1 | S30: =IF(AND(ROW()>=5,ROW()+6<=339),1,0) -> 1 | T30: =IF(AND(ROW()>=5,ROW()+12<=339),1,0) -> 1
A31: 2000-06 | B31: 29.8 | C31: 8.2772 | D31: =B31*C31 -> 246.66056 | E31: =100*LN(B31/B30) -> 7.1632979 | F31: =100*LN(C31/C30) -> -0.010872651 | G31: =100*LN(D31/D30) -> 7.1524252 | H31: 114.2 | I31: 102.9 | J31: 100.5 | K31: =H31-H30 -> 2.3 | L31: =I31-I30 -> 0.4 | M31: =J31-J30 -> 0.4 | N31: 107.1 | O31: 12.2 | P31: 11.2 | Q31: =IF(ROW()>=5,1,0) -> 1 | R31: =IF(AND(ROW()>=5,ROW()+3<=339),1,0) -> 1 | S31: =IF(AND(ROW()>=5,ROW()+6<=339),1,0) -> 1 | T31: =IF(AND(ROW()>=5,ROW()+12<=339),1,0) -> 1
A32: 2000-07 | B32: 28.68 | C32: 8.2794 | D32: =B32*C32 -> 237.45319 | E32: =100*LN(B32/B31) -> -3.8308378 | F32: =100*LN(C32/C31) -> 0.026575505 | G32: =100*LN(D32/D31) -> -3.8042623 | H32: 115.2 | I32: 104.5 | J32: 100.5 | K32: =H32-H31 -> 1 | L32: =I32-I31 -> 1.6 | M32: =J32-J31 -> 0 | N32: 108.6 | O32: 12.8 | P32: 11.4 | Q32: =IF(ROW()>=5,1,0) -> 1 | R32: =IF(AND(ROW()>=5,ROW()+3<=339),1,0) -> 1 | S32: =IF(AND(ROW()>=5,ROW()+6<=339),1,0) -> 1 | T32: =IF(AND(ROW()>=5,ROW()+12<=339),1,0) -> 1
A33: 2000-08 | B33: 30.2 | C33: 8.2796 | D33: =B33*C33 -> 250.04392 | E33: =100*LN(B33/B32) -> 5.1641909 | F33: =100*LN(C33/C32) -> 0.0024156048 | G33: =100*LN(D33/D32) -> 5.1666065 | H33: 117.8 | I33: 103.9 | J33: 100.3 | K33: =H33-H32 -> 2.6 | L33: =I33-I32 -> -0.6 | M33: =J33-J32 -> -0.2 | N33: 104.6 | O33: 12.8 | P33: 11.6 | Q33: =IF(ROW()>=5,1,0) -> 1 | R33: =IF(AND(ROW()>=5,ROW()+3<=339),1,0) -> 1 | S33: =IF(AND(ROW()>=5,ROW()+6<=339),1,0) -> 1 | T33: =IF(AND(ROW()>=5,ROW()+12<=339),1,0) -> 1
A34: 2000-09 | B34: 33.14 | C34: 8.2785 | D34: =B34*C34 -> 274.34949 | E34: =100*LN(B34/B33) -> 9.2899088 | F34: =100*LN(C34/C33) -> -0.013286549 | G34: =100*LN(D34/D33) -> 9.2766222 | H34: 117.6 | I34: 103.7 | J34: 100 | K34: =H34-H33 -> -0.2 | L34: =I34-I33 -> -0.2 | M34: =J34-J33 -> -0.3 | N34: 105.1 | O34: 12 | P34: 11.6 | Q34: =IF(ROW()>=5,1,0) -> 1 | R34: =IF(AND(ROW()>=5,ROW()+3<=339),1,0) -> 1 | S34: =IF(AND(ROW()>=5,ROW()+6<=339),1,0) -> 1 | T34: =IF(AND(ROW()>=5,ROW()+12<=339),1,0) -> 1
A35: 2000-10 | B35: 30.96 | C35: 8.2785 | D35: =B35*C35 -> 256.30236 | E35: =100*LN(B35/B34) -> -6.8044963 | F35: =100*LN(C35/C34) -> 0 | G35: =100*LN(D35/D34) -> -6.8044963 | H35: 118.1 | I35: 103.6 | J35: 100 | K35: =H35-H34 -> 0.5 | L35: =I35-I34 -> -0.1 | M35: =J35-J34 -> 0 | N35: 105.2 | O35: 11.4 | P35: 11.6 | Q35: =IF(ROW()>=5,1,0) -> 1 | R35: =IF(AND(ROW()>=5,ROW()+3<=339),1,0) -> 1 | S35: =IF(AND(ROW()>=5,ROW()+6<=339),1,0) -> 1 | T35: =IF(AND(ROW()>=5,ROW()+12<=339),1,0) -> 1
A36: 2000-11 | B36: 32.55 | C36: 8.2774 | D36: =B36*C36 -> 269.42937 | E36: =100*LN(B36/B35) -> 5.008132 | F36: =100*LN(C36/C35) -> -0.013288314 | G36: =100*LN(D36/D35) -> 4.9948437 | H36: 116.7 | I36: 103.5 | J36: 101.3 | K36: =H36-H35 -> -1.4 | L36: =I36-I35 -> -0.1 | M36: =J36-J35 -> 1.3 | N36: 105 | O36: 10.6 | P36: 11.5 | Q36: =IF(ROW()>=5,1,0) -> 1 | R36: =IF(AND(ROW()>=5,ROW()+3<=339),1,0) -> 1 | S36: =IF(AND(ROW()>=5,ROW()+6<=339),1,0) -> 1 | T36: =IF(AND(ROW()>=5,ROW()+12<=339),1,0) -> 1
A37: 2000-12 | B37: 25.66 | C37: 8.2771 | D37: =B37*C37 -> 212.39039 | E37: =100*LN(B37/B36) -> -23.784401 | F37: =100*LN(C37/C36) -> -0.0036243922 | G37: =100*LN(D37/D36) -> -23.788025 | H37: 113.5 | I37: 102.8 | J37: 101.5 | K37: =H37-H36 -> -3.2 | L37: =I37-I36 -> -0.7 | M37: =J37-J36 -> 0.2 | N37: 104.7 | O37: 10.4 | P37: 11.4 | Q37: =IF(ROW()>=5,1,0) -> 1 | R37: =IF(AND(ROW()>=5,ROW()+3<=339),1,0) -> 1 | S37: =IF(AND(ROW()>=5,ROW()+6<=339),1,0) -> 1 | T37: =IF(AND(ROW()>=5,ROW()+12<=339),1,0) -> 1
A38: 2001-01 | B38: 25.62 | C38: 8.2776 | D38: =B38*C38 -> 212.07211 | E38: =100*LN(B38/B37) -> -0.15600627 | F38: =100*LN(C38/C37) -> 0.0060405806 | G38: =100*LN(D38/D37) -> -0.14996569 | H38: 110 | I38: 101.4 | J38: 101.2 | K38: =H38-H37 -> -3.5 | L38: =I38-I37 -> -1.4 | M38: =J38-J37 -> -0.3 | N38: 103.6 | Q38: =IF(ROW()>=5,1,0) -> 1 | R38: =IF(AND(ROW()>=5,ROW()+3<=339),1,0) -> 1 | S38: =IF(AND(ROW()>=5,ROW()+6<=339),1,0) -> 1 | T38: =IF(AND(ROW()>=5,ROW()+12<=339),1,0) -> 1
A39: 2001-02 | B39: 27.5 | C39: 8.2771 | D39: =B39*C39 -> 227.62025 | E39: =100*LN(B39/B38) -> 7.0812708 | F39: =100*LN(C39/C38) -> -0.0060405806 | G39: =100*LN(D39/D38) -> 7.0752302 | H39: 105.9 | I39: 100.9 | J39: 100 | K39: =H39-H38 -> -4.1 | L39: =I39-I38 -> -0.5 | M39: =J39-J38 -> -1.2 | N39: 102.7 | O39: 19 | P39: 10.2 | Q39: =IF(ROW()>=5,1,0) -> 1 | R39: =IF(AND(ROW()>=5,ROW()+3<=339),1,0) -> 1 | S39: =IF(AND(ROW()>=5,ROW()+6<=339),1,0) -> 1 | T39: =IF(AND(ROW()>=5,ROW()+12<=339),1,0) -> 1
A40: 2001-03 | B40: 24.5 | C40: 8.2775 | D40: =B40*C40 -> 202.79875 | E40: =100*LN(B40/B39) -> -11.551289 | F40: =100*LN(C40/C39) -> 0.0048324937 | G40: =100*LN(D40/D39) -> -11.546456 | H40: 104.3 | I40: 100.2 | J40: 100.8 | K40: =H40-H39 -> -1.6 | L40: =I40-I39 -> -0.7 | M40: =J40-J39 -> 0.8 | N40: 102.1 | O40: 12.1 | P40: 11.2 | Q40: =IF(ROW()>=5,1,0) -> 1 | R40: =IF(AND(ROW()>=5,ROW()+3<=339),1,0) -> 1 | S40: =IF(AND(ROW()>=5,ROW()+6<=339),1,0) -> 1 | T40: =IF(AND(ROW()>=5,ROW()+12<=339),1,0) -> 1
...

Sheet Customs_134
A1: month | B1: HS | C1: import_quantity_kg | D1: import_value_cny | E1: import_unit_value_cny_per_kg | F1: dlog_import_quantity | G1: dlog_import_unit_value | H1: dlog_oil_rmb | I1: link1_origin
A2: 2015-01 | B2: 27090000 | C2: 27978648204 | D2: 79981726350 | E2: =D2/C2 -> 2.8586701 | F2: ="" | G2: ="" | H2: =Monthly_338!G206 -> -26.16593 | I2: =IF(ROW()>=6,1,0) -> 0
A3: 2015-02 | B3: 27090000 | C3: 25557194316 | D3: 59902470834 | E3: =D3/C3 -> 2.3438594 | F3: =100*LN(C3/C2) -> -9.05228 | G3: =100*LN(E3/E2) -> -19.855763 | H3: =Monthly_338!G207 -> 20.138222 | I3: =IF(ROW()>=6,1,0) -> 0
A4: 2015-03 | B4: 27090000 | C4: 26809943375 | D4: 66890312271 | E4: =D4/C4 -> 2.4949815 | F4: =100*LN(C4/C3) -> 4.7853985 | G4: =100*LN(E4/E3) -> 6.2482409 | H4: =Monthly_338!G208 -> -4.0893815 | I4: =IF(ROW()>=6,1,0) -> 0
A5: 2015-04 | B5: 27090000 | C5: 30286800453 | D5: 75787075883 | E5: =D5/C5 -> 2.5023137 | F5: =100*LN(C5/C4) -> 12.193915 | G5: =100*LN(E5/E4) -> 0.29344789 | H5: =Monthly_338!G209 -> 5.6881688 | I5: =IF(ROW()>=6,1,0) -> 0
A6: 2015-05 | B6: 27090000 | C6: 23249324628 | D6: 61590313859 | E6: =D6/C6 -> 2.6491227 | F6: =100*LN(C6/C5) -> -26.443591 | G6: =100*LN(E6/E5) -> 5.7012746 | H6: =Monthly_338!G210 -> 7.4222992 | I6: =IF(ROW()>=6,1,0) -> 1
A7: 2015-06 | B7: 27090000 | C7: 29493441442 | D7: 81871167033 | E7: =D7/C7 -> 2.7759109 | F7: =100*LN(C7/C6) -> 23.789183 | G7: =100*LN(E7/E6) -> 4.6750431 | H7: =Monthly_338!G211 -> -4.1146383 | I7: =IF(ROW()>=6,1,0) -> 1
A8: 2015-07 | B8: 27090000 | C8: 30706239392 | D8: 84697996577 | E8: =D8/C8 -> 2.7583318 | F8: =100*LN(C8/C7) -> 4.0297957 | G8: =100*LN(E8/E7) -> -0.63528866 | H8: =Monthly_338!G212 -> -8.2878226 | I8: =IF(ROW()>=6,1,0) -> 1
A9: 2015-08 | B9: 27090000 | C9: 26587571237 | D9: 68739421967 | E9: =D9/C9 -> 2.5853968 | F9: =100*LN(C9/C8) -> -14.402201 | G9: =100*LN(E9/E8) -> -6.4747074 | H9: =Monthly_338!G213 -> -17.472842 | I9: =IF(ROW()>=6,1,0) -> 1
A10: 2015-09 | B10: 27090000 | C10: 27949501844 | D10: 65648379952 | E10: =D10/C10 -> 2.3488211 | F10: =100*LN(C10/C9) -> 4.9955516 | G10: =100*LN(E10/E9) -> -9.5965455 | H10: =Monthly_338!G214 -> 2.7982552 | I10: =IF(ROW()>=6,1,0) -> 1
A11: 2015-10 | B11: 27090000 | C11: 26352357942 | D11: 59420349169 | E11: =D11/C11 -> 2.2548399 | F11: =100*LN(C11/C10) -> -5.884162 | G11: =100*LN(E11/E10) -> -4.0834557 | H11: =Monthly_338!G215 -> 1.4177533 | I11: =IF(ROW()>=6,1,0) -> 1
A12: 2015-11 | B12: 27090000 | C12: 27340925460 | D12: 61147166049 | E12: =D12/C12 -> 2.2364702 | F12: =100*LN(C12/C11) -> 3.6826924 | G12: =100*LN(E12/E11) -> -0.81801538 | H12: =Monthly_338!G216 -> -8.7688649 | I12: =IF(ROW()>=6,1,0) -> 1
A13: 2015-12 | B13: 27090000 | C13: 33170862438 | D13: 66921003539 | E13: =D13/C13 -> 2.0174635 | F13: =100*LN(C13/C12) -> 19.328717 | G13: =100*LN(E13/E12) -> -10.305782 | H13: =Monthly_338!G217 -> -13.917449 | I13: =IF(ROW()>=6,1,0) -> 1
A14: 2016-01 | B14: 27090000 | C14: 26683027055 | D14: 48095137382 | E14: =D14/C14 -> 1.8024618 | F14: =100*LN(C14/C13) -> -21.764418 | G14: =100*LN(E14/E13) -> -11.268761 | H14: =Monthly_338!G218 -> -19.461772 | I14: =IF(ROW()>=6,1,0) -> 1
... A135: 2026-02 | B135: 27090000 | C135: 48045363286 | D135: 155487504853 | E135: =D135/C135 -> 3.2362645 | F135: =100*LN(C135/C134) -> -1.7399823 | G135: =100*LN(E135/E134) -> 1.3452502 | H135: =Monthly_338!G339 -> 5.337288 | I135: =IF(ROW()>=6,1,0) -> 1

Sheet Fig2_observations
A1: month | B1: variable | C1: value | D1: available | E1: primary_lp_origin_h0 | F1: primary_lp_origin_h12
A2: 1998-01 | B2: brent_usd_per_bbl | C2: 15.19 | D2: 1 | E2: 0 | F2: 0
A3: 1998-01 | B3: cny_per_usd | C3: 8.3094 | D3: 1 | E3: 0 | F3: 0
A4: 1998-01 | B4: oil_rmb_cny_per_bbl | C4: 126.21979 | D4: 1 | E4: 0 | F4: 0
A5: 1998-01 | B5: fuel_index_yoy | C5: 105.9 | D5: 1 | E5: 0 | F5: 0
A6: 1998-01 | B6: ppi_index_yoy | C6: 98.7 | D6: 1 | E6: 0 | F6: 0
A7: 1998-01 | B7: cpi_index_yoy | C7: 100.3 | D7: 1 | E7: 0 | F7: 0
A8: 1998-01 | B8: purchase_index_yoy | C8: 99.6 | D8: 1 | E8: 0 | F8: 0
A9: 1998-01 | B9: import_quantity_kg | D9: 0 | E9: 0 | F9: 0
A10: 1998-01 | B10: import_value_cny | D10: 0 | E10: 0 | F10: 0
A11: 1998-01 | B11: import_unit_value_cny_per_kg | D11: 0 | E11: 0 | F11: 0
A12: 1998-01 | B12: dlog_oil_rmb | D12: 0 | E12: 0 | F12: 0
A13: 1998-01 | B13: d_fuel_power_inflation | D13: 0 | E13: 0 | F13: 0
A14: 1998-01 | B14: d_ppi_inflation | D14: 0 | E14: 0 | F14: 0
A15: 1998-01 | B15: d_cpi_inflation | D15: 0 | E15: 0 | F15: 0
A16: 1998-01 | B16: dlog_import_unit_value | D16: 0 | E16: 0 | F16: 0
A17: 1998-02 | B17: brent_usd_per_bbl | C17: 14.07 | D17: 1 | E17: 0 | F17: 0
A18: 1998-02 | B18: cny_per_usd | C18: 8.3072 | D18: 1 | E18: 0 | F18: 0
A19: 1998-02 | B19: oil_rmb_cny_per_bbl | C19: 116.8823 | D19: 1 | E19: 0 | F19: 0
A20: 1998-02 | B20: fuel_index_yoy | C20: 101.5 | D20: 1 | E20: 0 | F20: 0
A21: 1998-02 | B21: ppi_index_yoy | C21: 97.4 | D21: 1 | E21: 0 | F21: 0
A22: 1998-02 | B22: cpi_index_yoy | C22: 99.9 | D22: 1 | E22: 0 | F22: 0
A23: 1998-02 | B23: purchase_index_yoy | C23: 98.3 | D23: 1 | E23: 0 | F23: 0
A24: 1998-02 | B24: import_quantity_kg | D24: 0 | E24: 0 | F24: 0
A25: 1998-02 | B25: import_value_cny | D25: 0 | E25: 0 | F25: 0
A26: 1998-02 | B26: import_unit_value_cny_per_kg | D26: 0 | E26: 0 | F26: 0
A27: 1998-02 | B27: dlog_oil_rmb | C27: -7.6857241 | D27: 1 | E27: 0 | F27: 0
A28: 1998-02 | B28: d_fuel_power_inflation | C28: -4.4 | D28: 1 | E28: 0 | F28: 0
A29: 1998-02 | B29: d_ppi_inflation | C29: -1.3 | D29: 1 | E29: 0 | F29: 0
A30: 1998-02 | B30: d_cpi_inflation | C30: -0.4 | D30: 1 | E30: 0 | F30: 0
A31: 1998-02 | B31: dlog_import_unit_value | D31: 0 | E31: 0 | F31: 0
A32: 1998-03 | B32: brent_usd_per_bbl | C32: 13.1 | D32: 1 | E32: 0 | F32: 0
A33: 1998-03 | B33: cny_per_usd | C33: 8.3076 | D33: 1 | E33: 0 | F33: 0
A34: 1998-03 | B34: oil_rmb_cny_per_bbl | C34: 108.82956 | D34: 1 | E34: 0 | F34: 0
A35: 1998-03 | B35: fuel_index_yoy | C35: 100.7 | D35: 1 | E35: 0 | F35: 0
A36: 1998-03 | B36: ppi_index_yoy | C36: 96.8 | D36: 1 | E36: 0 | F36: 0
A37: 1998-03 | B37: cpi_index_yoy | C37: 100.7 | D37: 1 | E37: 0 | F37: 0
A38: 1998-03 | B38: purchase_index_yoy | C38: 97.7 | D38: 1 | E38: 0 | F38: 0
A39: 1998-03 | B39: import_quantity_kg | D39: 0 | E39: 0 | F39: 0
A40: 1998-03 | B40: import_value_cny | D40: 0 | E40: 0 | F40: 0
...

Sheet Dictionary
A1: variable | B1: units | C1: meaning_and_transformation | D1: provider_or_role
A2: month | B2: YYYY-MM | C2: Monthly calendar, not row-adjacent imputed records | D2: all
A3: brent_usd_per_bbl | B3: USD/barrel | C3: EIA monthly Brent RBRTE, as provided | D3: EIA
A4: cny_per_usd | B4: CNY/USD | C4: FRED EXCHUS monthly average, CNY per USD, no inversion | D4: FRED
A5: oil_rmb_cny_per_bbl | B5: CNY/barrel | C5: brent_usd_per_bbl x cny_per_usd | D5: Derived
A6: dlog_brent | B6: approx % | C6: 100 x ln(Brent_t/Brent_(t-1)) | D6: Derived
A7: dlog_fx | B7: approx % | C7: 100 x ln(FX_t/FX_(t-1)) | D7: Derived
A8: dlog_oil_rmb | B8: approx % | C8: 100 x ln(oil_rmb_t/oil_rmb_(t-1)); exact log identity with Brent and FX | D8: Derived
A9: fuel_index_yoy | B9: index; YoY=100 base | C9: Fuel and power purchase price index, previous-year same month=100 | D9: NBS
A10: ppi_index_yoy | B10: index; YoY=100 base | C10: Industrial producer factory-gate price index | D10: NBS
A11: cpi_index_yoy | B11: index; YoY=100 base | C11: Headline CPI index; four mutually exclusive source-year slices | D11: NBS
A12: d_fuel_power_inflation | B12: percentage points | C12: Fuel index_t-Fuel index_(t-1); monthly change in YoY inflation | D12: Derived
... A28: link1_origin | B28: 0/1 | C28: Fixed lag order p=3 Customs Link 1, origins start May 2015 | D28: Derived
A29: variable | C29: see README
A30: value | C30: see README
A31: available | B31: 0/1 | C31: Observed/defined value available in figure-data long table | D31: Derived
A32: primary_lp_origin_h0 | B32: 0/1 | C32: Macro LP origin eligibility flag for horizon zero | D32: Derived
A33: primary_lp_origin_h12 | B33: 0/1 | C33: Macro LP origin eligibility flag for horizon twelve | D33: Derived

Sheet Source_and_QA
A1: source | B1: series | C1: official_url | D1: distribution_note
A2: EIA Brent | B2: RBRTE | C2: https://www.eia.gov/dnav/pet/hist/LeafHandler.ashx?n=PET&s=RBRTE&f=M | D2: Original provider dataset; check Thomson Reuters credit and terms prior to redistributed supplement.
A3: Federal Reserve / FRED | B3: EXCHUS | C3: https://fred.stlouisfed.org/series/EXCHUS | D3: Monthly EXCHUS observations also included in GitHub release.
A4: NBS China | B4: CPI / PPI / Fuel / industrial purchase / industrial value added | C4: https://data.stats.gov.cn/ | D4: Official monthly query results; downstream reuse conditions must be assessed.
A5: China Customs | B5: HS27090000 monthly imports | C5: https://stats.customs.gov.cn/ | D5: First quantity kg; RMB value CNY; 134 months; conditions of public redistribution are author responsibility.
A7: QA measure | B7: Value
A8: Primary input SHA256 matches | B8: 10 / 10
A9: Calendar months (1998-01–2026-02) | B9: 338
A10: Customs months (2015-01–2026-02) | B10: 134
A11: Eligible LP origin h=0 | B11: 335
A12: Eligible LP origin h=12 | B12: 323
A13: Customs Link1 p=3 observations | B13: 130
A14: Excluded raw CPI placeholders | B14: The source OOXML values 66 and 40 are shared-string indices representing blank cells, not numeric CPI observations. No invalid CPI placeholders were included.
A15: Crude-oil HS code | B15: 27090000
A16: Excluded other customs code | B16: 27102000
A17: Quantitative independence | B17: Raw data -> stationary transformations only; no models refit for this file
A18: Reproduction limits | B18: The reconstructed Figure 2 observations were checked against the frozen 7,774-row source, including coverage, distributions, eligibility indicators and all 64 outliers. The historical source file is not separately redistributed.
